Workbook

Sheet README
A1: Culturdle — Question Bank v2 (trimmed and scored)
A3: Daily guessing game: two editions (Global, India) × three modes (Movie, Music, Icon). Six guesses; a new hint after every miss; four options on guess six.
A5: What changed from v1 (15,110 rows):
A6: • Scope narrowed to well-known, theatrically released films, charting songs and famous people and brands.
A7: • Every row has a Fame score from 0 to 10 built from public popularity signals (see the Scoring tab). Rows scoring below 6.0 were removed.
A8: • Streaming-premiere films and TV movies were removed regardless of score (theatrical releases only).
A9: • Hint ladders were rebuilt so each hint carries more information — the target is now 75–90% of players solving, not 45–55%.
A10: • Difficulty is re-derived from the Fame score within each edition: top 45% Easy, next 35% Medium, last 20% Hard.
A11: • Every removed row is listed on the Removed tab with its score and the reason, so any can be restored by hand.
A13: Hint ladders (v2):
A14: Movie: genre · industry · release year → director → plot moment (names masked) → two co-stars → lead actor · composer → title initials + options
A15: English song: genre · year → chart peak and weeks → album or another hit → another hit → artist → title initials + options
... A22: Still to do before launch: rewrite Movie “Moment” hints in original words (several are source synopsis text), and verify curated rows.

Sheet Scoring
A1: How the Fame score works
A2: Each signal is scaled 0–1 between its anchors, weighted and summed. Scores are then calibrated within each pool so that 6.0 is the keep line; anything below 6.0 is removed.
A4: Category | B4: Signal | C4: Measured by | D4: Weight | E4: Anchors (0 → full marks)
A5: Movie | B5: Audience reach | C5: IMDb vote count (log scale) | D5: 40% | E5: Global 20k → 1M · India 1.5k → 80k
A6: Movie | B6: Wikipedia reach | C6: Number of Wikipedia language editions with an article (Wikidata sitelinks) | D6: 25% | E6: Global 8 → 60 · India 4 → 30
A7: Movie | B7: Star power | C7: Lead actor's Wikipedia reach | D7: 15% | E7: Global 15 → 110 · India 8 → 70
A8: Movie | B8: Audience rating | C8: IMDb rating | D8: 10% | E8: 5.0 → 8.0
A9: Movie | B9: Era familiarity | C9: Release year (newer = more familiar) | D9: 10% | E9: ≥1990: 1 · 1975–89: 0.8 · 1960–74: 0.6 · older 0.4
A10: Movie | B10: Exclusion | C10: Streaming premiere: every Wikidata distributor is a streaming service AND released 2016+ (Global) / 2020+ (India), since older films list later OTT rights; or IMDb type TV movie / video. Duplicate answers keep the better-known copy. | D10: removed | E10: theatrical releases only
A11: English song | B11: Chart peak | C11: Billboard Hot 100 peak position | D11: 30% | E11: #10 → #1
A12: English song | B12: Chart longevity | C12: Weeks on the Hot 100 | D12: 20% | E12: 10 → 40 weeks
A13: English song | B13: Artist fame | C13: Artist's Wikipedia reach | D13: 30% | E13: 15 → 110
A14: English song | B14: Era familiarity | C14: Chart year | D14: 20% | E14: ≥1980: 1 · 1970s 0.75 · 1960s 0.5 · older 0.35
A15: Hindi song | B15: Film fame | C15: IMDb votes for the song's film (log scale) | D15: 35% | E15: 500 → 60k
... A24: Icon | B24: Screen presence | C24: Films in the bank (derived actors only) | D24: 15% | E24: 3 → 20 films
A27: Retention by pool
A28: Sheet | B28: Edition | C28: Rows in v1 | D28: Kept (live count) | E28: Removed (live count) | F28: Retained % | G28: Keep target
A29: Movies | B29: Global | C29: 2161 | D29: =COUNTIFS(Movies!$B:$B,$B29) -> 1650 | E29: =COUNTIFS(Removed!$B:$B,$A29,Removed!$C:$C,$B29) -> 511 | F29: =IFERROR(D29/C29,0) -> 0.7635354 | G29: 0.75
A30: Movies | B30: India | C30: 2124 | D30: =COUNTIFS(Movies!$B:$B,$B30) -> 1187 | E30: =COUNTIFS(Removed!$B:$B,$A30,Removed!$C:$C,$B30) -> 937 | F30: =IFERROR(D30/C30,0) -> 0.55885122 | G30: 0.55
A31: Music | B31: Global | C31: 5752 | D31: =COUNTIFS(Music!$B:$B,$B31) -> 3475 | E31: =COUNTIFS(Removed!$B:$B,$A31,Removed!$C:$C,$B31) -> 2277 | F31: =IFERROR(D31/C31,0) -> 0.60413769 | G31: 0.6
A32: Music | B32: India | C32: 3832 | D32: =COUNTIFS(Music!$B:$B,$B32) -> 2374 | E32: =COUNTIFS(Removed!$B:$B,$A32,Removed!$C:$C,$B32) -> 1458 | F32: =IFERROR(D32/C32,0) -> 0.61951983 | G32: 0.6
A33: Icons | B33: Global | C33: 835 | D33: =COUNTIFS(Icons!$B:$B,$B33) -> 671 | E33: =COUNTIFS(Removed!$B:$B,$A33,Removed!$C:$C,$B33) -> 164 | F33: =IFERROR(D33/C33,0) -> 0.80359281 | G33: 0.8
A34: Icons | B34: India | C34: 406 | D34: =COUNTIFS(Icons!$B:$B,$B34) -> 333 | E34: =COUNTIFS(Removed!$B:$B,$A34,Removed!$C:$C,$B34) -> 73 | F34: =IFERROR(D34/C34,0) -> 0.82019704 | G34: 0.8
A35: Total | C35: =SUM(C29:C34) -> 15110 | D35: =SUM(D29:D34) -> 9690 | E35: =SUM(E29:E34) -> 5420 | F35: =IFERROR(D35/C35,0) -> 0.64129715
A37: Blue = fixed inputs (v1 counts and keep targets). Black = formulas over the Movies, Music, Icons and Removed tabs.
A39: Difficulty mix of kept rows
A40: Sheet | B40: Edition | C40: Easy | D40: Medium | E40: Hard
A41: Movies | B41: Global | C41: =COUNTIFS(Movies!$B:$B,$B41,Movies!$D:$D,"Easy") -> 742 | D41: =COUNTIFS(Movies!$B:$B,$B41,Movies!$D:$D,"Medium") -> 578 | E41: =COUNTIFS(Movies!$B:$B,$B41,Movies!$D:$D,"Hard") -> 330
A42: Movies | B42: India | C42: =COUNTIFS(Movies!$B:$B,$B42,Movies!$D:$D,"Easy") -> 534 | D42: =COUNTIFS(Movies!$B:$B,$B42,Movies!$D:$D,"Medium") -> 415 | E42: =COUNTIFS(Movies!$B:$B,$B42,Movies!$D:$D,"Hard") -> 238
A43: Music | B43: Global | C43: =COUNTIFS(Music!$B:$B,$B43,Music!$D:$D,"Easy") -> 1564 | D43: =COUNTIFS(Music!$B:$B,$B43,Music!$D:$D,"Medium") -> 1216 | E43: =COUNTIFS(Music!$B:$B,$B43,Music!$D:$D,"Hard") -> 695
A44: Music | B44: India | C44: =COUNTIFS(Music!$B:$B,$B44,Music!$D:$D,"Easy") -> 1068 | D44: =COUNTIFS(Music!$B:$B,$B44,Music!$D:$D,"Medium") -> 831 | E44: =COUNTIFS(Music!$B:$B,$B44,Music!$D:$D,"Hard") -> 475
A45: Icons | B45: Global | C45: =COUNTIFS(Icons!$B:$B,$B45,Icons!$E:$E,"Easy") -> 302 | D45: =COUNTIFS(Icons!$B:$B,$B45,Icons!$E:$E,"Medium") -> 235 | E45: =COUNTIFS(Icons!$B:$B,$B45,Icons!$E:$E,"Hard") -> 134
A46: Icons | B46: India | C46: =COUNTIFS(Icons!$B:$B,$B46,Icons!$E:$E,"Easy") -> 150 | D46: =COUNTIFS(Icons!$B:$B,$B46,Icons!$E:$E,"Medium") -> 117 | E46: =COUNTIFS(Icons!$B:$B,$B46,Icons!$E:$E,"Hard") -> 66

Sheet Movies
A1: ID | B1: Edition | C1: Industry | D1: Difficulty | E1: Answer | F1: Accepted aliases | G1: Year | H1: Hint 1 (shown at start) | I1: Hint 2 (after miss 1) | J1: Hint 3 (after miss 2) | K1: Hint 4 (after miss 3) | L1: Hint 5 (after miss 4) | M1: Hint 6 (after miss 5, with options) | N1: Wrong option A | O1: Wrong option B | P1: Wrong option C | Q1: Reveal-card fact | R1: Director | S1: Music | T1: Lead | U1: Source | V1: Verify flag | W1: Fame score (0-10) | X1: Score signals
A2: MOV-G-00009 | B2: Global | C2: Hollywood | D2: Easy | E2: A Beautiful Mind | F2: Beautiful Mind | G2: 2001 | H2: Genre: Biography, Drama · Hollywood · released 2001 | I2: Directed by: Ron Howard | J2: Moment: At ____ struggles to make a worthwhile contribution to serve as his legacy to the world of mathematics. | K2: Co-stars: Jennifer Connelly, Ed Harris | L2: Lead: Russell Crowe · music by James Horner | M2: Title initials: A. B. M. (3 words) | N2: Coach Carter | O2: Jarhead | P2: The Queen | Q2: Released 2001-12-11; 135 min; worldwide gross about US$314 million (TMDB); tagline: "I need to believe that something extra ordinary is possible..." | R2: Ron Howard | S2: James Horner | T2: Russell Crowe | U2: TMDB 5000 (vote count ≥300); cast from Wikipedia Movie Data | V2: Plot hint is source synopsis text – rewrite before launch; Hints rebuilt Oct 2026 for a 75–90% solve target | W2: 10 | X2: IMDb 1,066,185 votes · 8.2/10 · 86 Wikipedias · lead fame 125
A3: MOV-G-00028 | B3: Global | C3: Hollywood | D3: Easy | E3: Avengers: Endgame | F3: Avengers Endgame | G3: 2019 | H3: Genre: Action, Adventure · Hollywood · released 2019 | I3: Directed by: Anthony and Joe Russo | J3: Moment: Survivors travel through time to reverse the snap | K3: Co-stars: Chris Evans, Mark Ruffalo | L3: Lead: Robert Downey Jr. · music by Alan Silvestri | M3: Title initials: A. E. (2 words) | N3: Cop Out | O3: Tower Heist | P3: The Huntsman: Winter's War | Q3: Released 2019 | R3: Anthony and Joe Russo | S3: Alan Silvestri | T3: Robert Downey Jr. | U3: Curated by Claude; director and lead cross-checked against Wikipedia Movie Data where available | V3: Curated (2017–2025 gap in TMDB) – plot line written by Claude; Wikipedia cross-check: director OK, lead OK; Hints rebuilt Oct 2026 for a 75–90% solve target | W3: 10 | X3: IMDb 1,500,097 votes · 8.4/10 · 90 Wikipedias · lead fame 112
A4: MOV-G-00029 | B4: Global | C4: Hollywood | D4: Easy | E4: Avengers: Infinity War | F4: Avengers Infinity War | G4: 2018 | H4: Genre: Action, Adventure · Hollywood · released 2018 | I4: Directed by: Anthony and Joe Russo | J4: Moment: A villain collects six stones and wipes out half of all life with a snap | K4: Co-stars: Chris Hemsworth, Mark Ruffalo | L4: Lead: Robert Downey Jr. · music by Alan Silvestri | M4: Title initials: A. I. W. (3 words) | N4: The Legend of Hercules | O4: The Book of Eli | P4: Kung Fu Panda 3 | Q4: Released 2018 | R4: Anthony and Joe Russo | S4: Alan Silvestri | T4: Robert Downey Jr. | U4: Curated by Claude; director and lead cross-checked against Wikipedia Movie Data where available | V4: Curated (2017–2025 gap in TMDB) – plot line written by Claude; Wikipedia cross-check: director OK, lead OK; Hints rebuilt Oct 2026 for a 75–90% solve target | W4: 10 | X4: IMDb 1,417,740 votes · 8.4/10 · 86 Wikipedias · lead fame 112
A5: MOV-G-00043 | B5: Global | C5: Hollywood | D5: Easy | E5: Braveheart | G5: 1995 | H5: Genre: Drama, War · Hollywood · released 1995 | I5: Directed by: Mel Gibson | J5: Moment: Enraged at the slaughter of ____, his new bride and childhood love, ____ warrior ____ slays a platoon of the local ____ lord's soldiers. | K5: Co-stars: Sophie Marceau, Catherine McCormack | L5: Lead: Mel Gibson · music by James Horner | M5: Title: one word, 10 letters, starts with 'B' | N5: The Last of the Mohicans | O5: Enemy of the State | P5: Die Hard: With a Vengeance | Q5: Released 1995-05-24; 177 min; worldwide gross about US$210 million (TMDB); tagline: "Every man dies. Not every man truly lives." | R5: Mel Gibson | S5: James Horner | T5: Mel Gibson | U5: TMDB 5000 (vote count ≥300); cast from Wikipedia Movie Data | V5: Plot hint is source synopsis text – rewrite before launch; Hints rebuilt Oct 2026 for a 75–90% solve target | W5: 10 | X5: IMDb 1,174,695 votes · 8.3/10 · 92 Wikipedias · lead fame 119
A6: MOV-G-00052 | B6: Global | C6: Hollywood | D6: Easy | E6: Catch Me If You Can | G6: 2002 | H6: Genre: Biography, Crime · Hollywood · released 2002 | I6: Directed by: Steven Spielberg | J6: Moment: A true story about ____. | K6: Co-stars: Tom Hanks, Christopher Walken | L6: Lead: Leonardo DiCaprio · music by John Williams | M6: Title initials: C. M. I. Y. C. (5 words) | N6: Million Dollar Baby | O6: Vicky Cristina Barcelona | P6: The Young Victoria | Q6: Released 2002-12-25; 141 min; worldwide gross about US$352 million (TMDB); tagline: "The true story of a real fake." | R6: Steven Spielberg | S6: John Williams | T6: Leonardo DiCaprio | U6: TMDB 5000 (vote count ≥300); cast from Wikipedia Movie Data | V6: Plot hint is source synopsis text – rewrite before launch; Hints rebuilt Oct 2026 for a 75–90% solve target | W6: 10 | X6: IMDb 1,269,603 votes · 8.1/10 · 76 Wikipedias · lead fame 149
A7: MOV-G-00078 | B7: Global | C7: Hollywood | D7: Easy | E7: Eternal Sunshine of the Spotless Mind | G7: 2004 | H7: Genre: Drama, Romance · Hollywood · released 2004 | I7: Directed by: Michel Gondry | J7: Moment: Joel ____, heartbroken that his girlfriend underwent a procedure to erase him from her memory, decides to do the same. | K7: Co-stars: Kate Winslet, Kirsten Dunst | L7: Lead: Jim Carrey · music by Jon Brion | M7: Title initials: E. S. O. T. S. M. (6 words) | N7: Unbreakable | O7: Primer | P7: The Mist | Q7: Released 2004-03-19; 108 min; worldwide gross about US$72 million (TMDB); tagline: "You can erase someone from your mind. Getting them out of your heart is another story." | R7: Michel Gondry | S7: Jon Brion | T7: Jim Carrey | U7: TMDB 5000 (vote count ≥300); cast from Wikipedia Movie Data | V7: Plot hint is source synopsis text – rewrite before launch; Hints rebuilt Oct 2026 for a 75–90% solve target | W7: 10 | X7: IMDb 1,199,593 votes · 8.3/10 · 67 Wikipedias · lead fame 126
A8: MOV-G-00084 | B8: Global | C8: Hollywood | D8: Easy | E8: Fight Club | G8: 1999 | H8: Genre: Crime, Drama · Hollywood · released 1999 | I8: Directed by: David Fincher | J8: Moment: A ticking-time-bomb insomniac and a slippery soap salesman channel primal male aggression into a shocking new form of therapy. | K8: Co-stars: Edward Norton, Helena Bonham Carter | L8: Lead: Brad Pitt · music by John King & Michael Simpson | M8: Title initials: F. C. (2 words) | N8: The Shawshank Redemption | O8: Good Will Hunting | P8: Ever After: A Cinderella Story | Q8: Released 1999-10-15; 139 min; worldwide gross about US$101 million (TMDB); tagline: "Mischief. Mayhem. Soap." | R8: David Fincher | S8: John King & Michael Simpson | T8: Brad Pitt | U8: TMDB 5000 (vote count ≥300); cast from Wikipedia Movie Data | V8: Plot hint is source synopsis text – rewrite before launch; Hints rebuilt Oct 2026 for a 75–90% solve target | W8: 10 | X8: IMDb 2,673,124 votes · 8.8/10 · 102 Wikipedias · lead fame 147
A9: MOV-G-00087 | B9: Global | C9: Hollywood | D9: Easy | E9: Forrest Gump | G9: 1994 | H9: Genre: Drama, Romance · Hollywood · released 1994 | I9: Directed by: Robert Zemeckis | J9: Moment: A man with a low ____ has accomplished great things in his life and been present during significant historic events - in each case, far exceeding what anyone imagined he could do. | K9: Co-stars: Robin Wright Penn, Haley Joel Osment | L9: Lead: Tom Hanks · music by Alan Silvestri | M9: Title initials: F. G. (2 words) | N9: Dazed and Confused | O9: Four Weddings and a Funeral | P9: Man on the Moon | Q9: Released 1994-07-06; 142 min; worldwide gross about US$678 million (TMDB); tagline: "The world will never be the same, once you've seen it through the eyes of Forrest Gump." | R9: Robert Zemeckis | S9: Alan Silvestri | T9: Tom Hanks | U9: TMDB 5000 (vote count ≥300); cast from Wikipedia Movie Data | V9: Plot hint is source synopsis text – rewrite before launch; Hints rebuilt Oct 2026 for a 75–90% solve target | W9: 10 | X9: IMDb 2,544,942 votes · 8.8/10 · 137 Wikipedias · lead fame 136
A10: MOV-G-00094 | B10: Global | C10: Hollywood | D10: Easy | E10: Gladiator | G10: 2000 | H10: Genre: Action, Adventure · Hollywood · released 2000 | I10: Directed by: Ridley Scott | J10: Moment: In the year 180, the death of emperor ____ throws the ____ into chaos. | K10: Co-stars: Joaquin Phoenix, Connie Nielsen | L10: Lead: Russell Crowe · music by Hans Zimmer & Lisa Gerrard | M10: Title: one word, 9 letters, starts with 'G' | N10: The Scorpion King | O10: Get Smart | P10: Shaft | Q10: Released 2000-05-01; 155 min; worldwide gross about US$458 million (TMDB); tagline: "A Hero Will Rise." | R10: Ridley Scott | S10: Hans Zimmer & Lisa Gerrard | T10: Russell Crowe | U10: TMDB 5000 (vote count ≥300); cast from Wikipedia Movie Data | V10: Plot hint is source synopsis text – rewrite before launch; Hints rebuilt Oct 2026 for a 75–90% solve target | W10: 10 | X10: IMDb 1,888,826 votes · 8.5/10 · 108 Wikipedias · lead fame 125
A11: MOV-G-00095 | B11: Global | C11: Hollywood | D11: Easy | E11: Gone Girl | G11: 2014 | H11: Genre: Drama, Mystery · Hollywood · released 2014 | I11: Directed by: David Fincher | J11: Moment: With his wife's disappearance having become the focus of an intense media circus, a man sees the spotlight turned on him when it's suspected that he may not be innocent. | K11: Co-stars: Rosamund Pike, Neil Patrick Harris | L11: Lead: Ben Affleck · music by Trent Reznor & Atticus Ross | M11: Title initials: G. G. (2 words) | N11: Nerve | O11: The Witch | P11: The Crazies | Q11: Released 2014-10-01; 145 min; worldwide gross about US$369 million (TMDB); tagline: "You don't know what you've got 'til it's..." | R11: David Fincher | S11: Trent Reznor & Atticus Ross | T11: Ben Affleck | U11: TMDB 5000 (vote count ≥300); cast from Wikipedia Movie Data | V11: Plot hint is source synopsis text – rewrite before launch; Hints rebuilt Oct 2026 for a 75–90% solve target | W11: 10 | X11: IMDb 1,191,907 votes · 8.1/10 · 60 Wikipedias · lead fame 112
A12: MOV-G-00096 | B12: Global | C12: Hollywood | D12: Easy | E12: Good Will Hunting | G12: 1997 | H12: Genre: Drama, Romance · Hollywood · released 1997 | I12: Directed by: Gus Van Sant | J12: Moment: ____ has a genius-level ____ but chooses to work as a janitor at ____. | K12: Co-stars: Robin Williams, Ben Affleck | L12: Lead: Matt Damon · music by Danny Elfman | M12: Title initials: G. W. H. (3 words) | N12: Contact | O12: The Pelican Brief | P12: American History X | Q12: Released 1997-12-05; 126 min; worldwide gross about US$226 million (TMDB); tagline: "Some people can never believe in themselves, until someone believes in them." | R12: Gus Van Sant | S12: Danny Elfman | T12: Matt Damon | U12: TMDB 5000 (vote count ≥300); cast from Wikipedia Movie Data | V12: Plot hint is source synopsis text – rewrite before launch; Hints rebuilt Oct 2026 for a 75–90% solve target | W12: 10 | X12: IMDb 1,248,120 votes · 8.4/10 · 70 Wikipedias · lead fame 114
A13: MOV-G-00097 | B13: Global | C13: Hollywood | D13: Easy | E13: GoodFellas | G13: 1990 | H13: Genre: Biography, Crime · Hollywood · released 1990 | I13: Directed by: Martin Scorsese | J13: Moment: The true story of ____, a half-Irish, half-Sicilian ____ kid who is adopted by neighbourhood gangsters at an early age and climbs the ranks of a ____ family under the guidance of ____. | K13: Co-stars: Ray Liotta, Joe Pesci | L13: Lead: Robert De Niro | M13: Title: one word, 10 letters, starts with 'G' | N13: The Bridges of Madison County | O13: Fight Club | P13: Patriot Games | Q13: Released 1990-09-12; 145 min; worldwide gross about US$47 million (TMDB); tagline: "Three Decades of Life in the Mafia." | R13: Martin Scorsese | T13: Robert De Niro | U13: TMDB 5000 (vote count ≥300); cast from Wikipedia Movie Data | V13: Plot hint is source synopsis text – rewrite before launch; Hints rebuilt Oct 2026 for a 75–90% solve target | W13: 10 | X13: IMDb 1,418,891 votes · 8.7/10 · 73 Wikipedias · lead fame 139
A14: MOV-G-00100 | B14: Global | C14: Hollywood | D14: Easy | E14: Guardians of the Galaxy | G14: 2014 | H14: Genre: Action, Adventure · Hollywood · released 2014 | I14: Directed by: James Gunn | J14: Moment: Light years from ____, 26 years after being abducted, ____ finds himself the prime target of a manhunt after discovering an orb wanted by ____ the ____. | K14: Co-stars: Zoe Saldana, Dave Bautista | L14: Lead: Chris Pratt · music by Tyler Bates | M14: Title initials: G. O. T. G. (4 words) | N14: No Escape | O14: Killer Elite | P14: Sucker Punch | Q14: Released 2014-07-30; 121 min; worldwide gross about US$773 million (TMDB); tagline: "All heroes start somewhere." | R14: James Gunn | S14: Tyler Bates | T14: Chris Pratt | U14: TMDB 5000 (vote count ≥300); cast from Wikipedia Movie Data | V14: Plot hint is source synopsis text – rewrite before launch; Hints rebuilt Oct 2026 for a 75–90% solve target | W14: 10 | X14: IMDb 1,388,962 votes · 8.0/10 · 72 Wikipedias · lead fame 127
A15: MOV-G-00120 | B15: Global | C15: Hollywood | D15: Easy | E15: Inception | G15: 2010 | H15: Genre: Adventure, Sci-Fi · Hollywood · released 2010 | I15: Directed by: Christopher Nolan | J15: Moment: Cobb, a skilled thief who commits corporate espionage by infiltrating the subconscious of his targets is offered a chance to regain his old life as payment for a task considered to be impossible: "____", the… | K15: Co-stars: Ken Watanabe, Joseph Gordon-Levitt | L15: Lead: Leonardo DiCaprio · music by Hans Zimmer | M15: Title: one word, 9 letters, starts with 'I' | N15: The Last Stand | O15: The Tourist | P15: 30 Minutes or Less | Q15: Released 2010-07-14; 148 min; worldwide gross about US$826 million (TMDB); tagline: "Your mind is the scene of the crime." | R15: Christopher Nolan | S15: Hans Zimmer | T15: Leonardo DiCaprio | U15: TMDB 5000 (vote count ≥300); cast from Wikipedia Movie Data | V15: Plot hint is source synopsis text – rewrite before launch; Hints rebuilt Oct 2026 for a 75–90% solve target | W15: 10 | X15: IMDb 2,880,007 votes · 8.8/10 · 97 Wikipedias · lead fame 149
A16: MOV-G-00124 | B16: Global | C16: Hollywood | D16: Easy | E16: Inglourious Basterds | G16: 2009 | H16: Genre: Drama, War · Hollywood · released 2009 | I16: Directed by: Quentin Tarantino | J16: Moment: In Nazi-occupied ____ during ____, a group of Jewish-American soldiers known as "The ____" are chosen specifically to spread fear throughout the ____ by scalping and brutally killing ____. | K16: Co-stars: Mélanie Laurent, Christoph Waltz | L16: Lead: Brad Pitt | M16: Title initials: I. B. (2 words) | N16: Finding Forrester | O16: Rocky Balboa | P16: Syriana | Q16: Released 2009-08-18; 153 min; worldwide gross about US$319 million (TMDB); tagline: "Once upon a time in Nazi occupied France..." | R16: Quentin Tarantino | T16: Brad Pitt | U16: TMDB 5000 (vote count ≥300); cast from Wikipedia Movie Data | V16: Plot hint is source synopsis text – rewrite before launch; Hints rebuilt Oct 2026 for a 75–90% solve target | W16: 10 | X16: IMDb 1,824,292 votes · 8.4/10 · 80 Wikipedias · lead fame 147
A17: MOV-G-00130 | B17: Global | C17: Hollywood | D17: Easy | E17: Iron Man | G17: 2008 | H17: Genre: Action, Adventure · Hollywood · released 2008 | I17: Directed by: Jon Favreau | J17: Moment: After being held captive in an ____ cave, billionaire engineer ____ creates a unique weaponized suit of armor to fight evil. | K17: Co-stars: Terrence Howard, Jeff Bridges | L17: Lead: Robert Downey Jr. · music by Ramin Djawadi | M17: Title initials: I. M. (2 words) | N17: Lara Croft Tomb Raider: The Cradle of Life | O17: Sahara | P17: Kill Bill: Vol. 2 | Q17: Released 2008-04-30; 126 min; worldwide gross about US$585 million (TMDB); tagline: "Heroes aren't born. They're built." | R17: Jon Favreau | S17: Ramin Djawadi | T17: Robert Downey Jr. | U17: TMDB 5000 (vote count ≥300); cast from Wikipedia Movie Data | V17: Plot hint is source synopsis text – rewrite before launch; Hints rebuilt Oct 2026 for a 75–90% solve target | W17: 10 | X17: IMDb 1,254,769 votes · 7.9/10 · 84 Wikipedias · lead fame 112
A18: MOV-G-00198 | B18: Global | C18: Hollywood | D18: Easy | E18: Pulp Fiction | G18: 1994 | H18: Genre: Crime, Drama · Hollywood · released 1994 | I18: Directed by: Quentin Tarantino | J18: Moment: A burger-loving hit man, his philosophical partner, a drug-addled gangster's moll and a washed-up boxer converge in this sprawling, comedic crime caper. | K18: Co-stars: Samuel L. Jackson, Bruce Willis | L18: Lead: John Travolta · music by Mary Ramos | M18: Title initials: P. F. (2 words) | N18: The Talented Mr. Ripley | O18: Gattaca | P18: The Thirteenth Floor | Q18: Released 1994-10-08; 154 min; worldwide gross about US$214 million (TMDB); tagline: "Just because you are a character doesn't mean you have character." | R18: Quentin Tarantino | S18: Mary Ramos | T18: John Travolta | U18: TMDB 5000 (vote count ≥300); cast from Wikipedia Movie Data | V18: Plot hint is source synopsis text – rewrite before launch; Hints rebuilt Oct 2026 for a 75–90% solve target | W18: 10 | X18: IMDb 2,476,095 votes · 8.8/10 · 107 Wikipedias · lead fame 117
A19: MOV-G-00209 | B19: Global | C19: Hollywood | D19: Easy | E19: Saving Private Ryan | G19: 1998 | H19: Genre: Drama, War · Hollywood · released 1998 | I19: Directed by: Steven Spielberg | J19: Moment: As U.S. | K19: Co-stars: Edward Burns, Matt Damon | L19: Lead: Tom Hanks · music by John Williams | M19: Title initials: S. P. R. (3 words) | N19: The Bone Collector | O19: Fight Club | P19: Schindler's List | Q19: Released 1998-07-24; 169 min; worldwide gross about US$482 million (TMDB); tagline: "The mission is a man." | R19: Steven Spielberg | S19: John Williams | T19: Tom Hanks | U19: TMDB 5000 (vote count ≥300); cast from Wikipedia Movie Data | V19: Plot hint is source synopsis text – rewrite before launch; Hints rebuilt Oct 2026 for a 75–90% solve target | W19: 10 | X19: IMDb 1,667,972 votes · 8.6/10 · 86 Wikipedias · lead fame 136
A20: MOV-G-00212 | B20: Global | C20: Hollywood | D20: Easy | E20: Se7en | G20: 1995 | H20: Genre: Crime, Drama · Hollywood · released 1995 | I20: Directed by: David Fincher | J20: Moment: Two homicide detectives are on a desperate hunt for a serial killer whose crimes are based on the "seven deadly sins" in this dark and haunting film that takes viewers from the tortured remains of one victim to the next. | K20: Co-stars: Morgan Freeman | L20: Lead: Brad Pitt · music by Howard Shore | M20: Title: one word, 5 letters, starts with 'S' | N20: Four Rooms | O20: Boys Don't Cry | P20: Boyz n the Hood | Q20: Released 1995-09-22; 127 min; worldwide gross about US$327 million (TMDB); tagline: "Seven deadly sins. Seven ways to die." | R20: David Fincher | S20: Howard Shore | T20: Brad Pitt | U20: TMDB 5000 (vote count ≥300); cast from Wikipedia Movie Data | V20: Plot hint is source synopsis text – rewrite before launch; Hints rebuilt Oct 2026 for a 75–90% solve target | W20: 10 | X20: IMDb 2,068,870 votes · 8.6/10 · 73 Wikipedias · lead fame 147
A21: MOV-G-00217 | B21: Global | C21: Hollywood | D21: Easy | E21: Shutter Island | G21: 2010 | H21: Genre: Mystery, Thriller · Hollywood · released 2010 | I21: Directed by: Martin Scorsese | J21: Moment: World ____ soldier-turned-U.S. | K21: Co-stars: Mark Ruffalo, Ben Kingsley | L21: Lead: Leonardo DiCaprio | M21: Title initials: S. I. (2 words) | N21: Remember Me | O21: Rush | P21: The Martian | Q21: Released 2010-02-18; 138 min; worldwide gross about US$295 million (TMDB); tagline: "Someone is missing." | R21: Martin Scorsese | T21: Leonardo DiCaprio | U21: TMDB 5000 (vote count ≥300); cast from Wikipedia Movie Data | V21: Plot hint is source synopsis text – rewrite before launch; Hints rebuilt Oct 2026 for a 75–90% solve target | W21: 10 | X21: IMDb 1,691,256 votes · 8.2/10 · 71 Wikipedias · lead fame 149
A22: MOV-G-00233 | B22: Global | C22: Hollywood | D22: Easy | E22: Spider-Man: No Way Home | F22: SpiderMan No Way Home | G22: 2021 | H22: Genre: Action, Adventure · Hollywood · released 2021 | I22: Directed by: Jon Watts | J22: Moment: A spell goes wrong and villains from other universes arrive | K22: Co-stars: Benedict Cumberbatch, Zendaya | L22: Lead: Tom Holland · music by Michael Giacchino | M22: Title initials: S. N. W. H. (4 words) | N22: The Batman | O22: No Time to Die | P22: Shang-Chi and the Legend of the Ten Rings | Q22: Released 2021 | R22: Jon Watts | S22: Michael Giacchino | T22: Tom Holland | U22: Curated by Claude; director and lead cross-checked against Wikipedia Movie Data where available | V22: Curated (2017–2025 gap in TMDB) – plot line written by Claude; Wikipedia cross-check: director OK, lead OK; Hints rebuilt Oct 2026 for a 75–90% solve target | W22: 10 | X22: IMDb 1,081,846 votes · 8.1/10 · 70 Wikipedias · lead fame 118
A23: MOV-G-00252 | B23: Global | C23: Hollywood | D23: Easy | E23: Terminator 2: Judgment Day | F23: Terminator 2 Judgment Day | G23: 1991 | H23: Genre: Action, Adventure · Hollywood · released 1991 | I23: Directed by: James Cameron | J23: Moment: Nearly 10 years have passed since ____ was targeted for termination by a cyborg from the future. | K23: Co-stars: Linda Hamilton, Robert Patrick | L23: Lead: Arnold Schwarzenegger · music by Brad Fiedel | M23: Title initials: T. 2. J. D. (4 words) | N23: Speed 2: Cruise Control | O23: eXistenZ | P23: The Last of the Mohicans | Q23: Released 1991-07-01; 137 min; worldwide gross about US$520 million (TMDB); tagline: "It's nothing personal." | R23: James Cameron | S23: Brad Fiedel | T23: Arnold Schwarzenegger | U23: TMDB 5000 (vote count ≥300); cast from Wikipedia Movie Data | V23: Plot hint is source synopsis text – rewrite before launch; Hints rebuilt Oct 2026 for a 75–90% solve target | W23: 10 | X23: IMDb 1,306,414 votes · 8.6/10 · 93 Wikipedias · lead fame 153
A24: MOV-G-00256 | B24: Global | C24: Hollywood | D24: Easy | E24: The Avengers | F24: Avengers | G24: 2012 | H24: Genre: Action, Sci-Fi · Hollywood · released 2012 | I24: Directed by: Joss Whedon | J24: Moment: When an unexpected enemy emerges and threatens global safety and security, ____, director of the international peacekeeping agency known as S.H.I.E.L.D., finds himself in need of a team to pull the world back from… | K24: Co-stars: Chris Evans, Chris Hemsworth | L24: Lead: Robert Downey Jr. · music by Alan Silvestri | M24: Title initials: T. A. (2 words) | N24: Skyline | O24: Terminator Genisys | P24: The Hunger Games | Q24: Released 2012-04-25; 143 min; worldwide gross about US$1,520 million (TMDB); tagline: "Some assembly required." | R24: Joss Whedon | S24: Alan Silvestri | T24: Robert Downey Jr. | U24: TMDB 5000 (vote count ≥300); cast from Wikipedia Movie Data | V24: Plot hint is source synopsis text – rewrite before launch; Hints rebuilt Oct 2026 for a 75–90% solve target | W24: 10 | X24: IMDb 1,587,985 votes · 8.0/10 · 96 Wikipedias · lead fame 112
A25: MOV-G-00270 | B25: Global | C25: Hollywood | D25: Easy | E25: The Departed | F25: Departed | G25: 2006 | H25: Genre: Crime, Drama · Hollywood · released 2006 | I25: Directed by: Martin Scorsese | J25: Moment: To take down ____, the police send in one of their own to infiltrate the underworld, not realizing the syndicate has done likewise. | K25: Co-stars: Matt Damon, Jack Nicholson | L25: Lead: Leonardo DiCaprio · music by Howard Shore | M25: Title initials: T. D. (2 words) | N25: Dancer in the Dark | O25: The Life of David Gale | P25: Chloe | Q25: Released 2006-10-05; 151 min; worldwide gross about US$290 million (TMDB); tagline: "Lies. Betrayal. Sacrifice. How far will you take it?" | R25: Martin Scorsese | S25: Howard Shore | T25: Leonardo DiCaprio | U25: TMDB 5000 (vote count ≥300); cast from Wikipedia Movie Data | V25: Plot hint is source synopsis text – rewrite before launch; Hints rebuilt Oct 2026 for a 75–90% solve target | W25: 10 | X25: IMDb 1,584,785 votes · 8.5/10 · 80 Wikipedias · lead fame 149
A26: MOV-G-00283 | B26: Global | C26: Hollywood | D26: Easy | E26: The Green Mile | F26: Green Mile | G26: 1999 | H26: Genre: Crime, Drama · Hollywood · released 1999 | I26: Directed by: Frank Darabont | J26: Moment: A supernatural tale set on death row in a ____ prison, where gentle giant ____ possesses the mysterious power to heal people's ailments. | K26: Co-stars: David Morse, Bonnie Hunt | L26: Lead: Tom Hanks · music by Thomas Newman | M26: Title initials: T. G. M. (3 words) | N26: Meet Joe Black | O26: DragonHeart | P26: The Santa Clause | Q26: Released 1999-12-10; 189 min; worldwide gross about US$285 million (TMDB); tagline: "Miracles do happen." | R26: Frank Darabont | S26: Thomas Newman | T26: Tom Hanks | U26: TMDB 5000 (vote count ≥300); cast from Wikipedia Movie Data | V26: Plot hint is source synopsis text – rewrite before launch; Hints rebuilt Oct 2026 for a 75–90% solve target | W26: 10 | X26: IMDb 1,591,837 votes · 8.6/10 · 77 Wikipedias · lead fame 136
A27: MOV-G-00304 | B27: Global | C27: Hollywood | D27: Easy | E27: The Martian | F27: Martian | G27: 2015 | H27: Genre: Adventure, Drama · Hollywood · released 2015 | I27: Directed by: Ridley Scott | J27: Moment: During a manned mission to ____ is presumed dead after a fierce storm and left behind by his crew. | K27: Co-stars: Jessica Chastain, Kristen Wiig | L27: Lead: Matt Damon · music by Harry Gregson-Williams | M27: Title initials: T. M. (2 words) | N27: Dear John | O27: The Giver | P27: This Is Where I Leave You | Q27: Released 2015-09-30; 141 min; worldwide gross about US$630 million (TMDB); tagline: "Bring Him Home" | R27: Ridley Scott | S27: Harry Gregson-Williams | T27: Matt Damon | U27: TMDB 5000 (vote count ≥300); cast from Wikipedia Movie Data | V27: Plot hint is source synopsis text – rewrite before launch; Hints rebuilt Oct 2026 for a 75–90% solve target | W27: 10 | X27: IMDb 1,033,635 votes · 8.0/10 · 72 Wikipedias · lead fame 114
A28: MOV-G-00305 | B28: Global | C28: Hollywood | D28: Easy | E28: The Matrix | F28: Matrix | G28: 1999 | H28: Genre: Action, Sci-Fi · Hollywood · released 1999 | I28: Directed by: Lilly Wachowski | J28: Moment: Set in the 22nd century, The ____ tells the story of a computer hacker who joins a group of underground insurgents fighting the vast and powerful computers who now rule the earth. | K28: Co-stars: Laurence Fishburne, Carrie-Anne Moss | L28: Lead: Keanu Reeves · music by Don Davis | M28: Title initials: T. M. (2 words) | N28: The Man in the Iron Mask | O28: Deep Impact | P28: Bad Boys | Q28: Released 1999-03-30; 136 min; worldwide gross about US$464 million (TMDB); tagline: "Welcome to the Real World." | R28: Lilly Wachowski | S28: Don Davis | T28: Keanu Reeves | U28: TMDB 5000 (vote count ≥300); cast from Wikipedia Movie Data | V28: Plot hint is source synopsis text – rewrite before launch; Hints rebuilt Oct 2026 for a 75–90% solve target | W28: 10 | X28: IMDb 2,286,709 votes · 8.7/10 · 114 Wikipedias · lead fame 124
A29: MOV-G-00313 | B29: Global | C29: Hollywood | D29: Easy | E29: The Revenant | F29: Revenant | G29: 2015 | H29: Genre: Action, Drama · Hollywood · released 2015 | I29: Directed by: Alejandro Gonz\u00e1lez I\u00f1\u00e1rritu | J29: Moment: In the 1820s, a frontiersman, ____, sets out on a path of vengeance against those who left him for dead after a bear mauling. | K29: Co-stars: Tom Hardy | L29: Lead: Leonardo DiCaprio · music by Ryuichi Sakamoto & Carsten Nicolai | M29: Title initials: T. R. (2 words) | N29: Sanctum | O29: The Counselor | P29: This Is 40 | Q29: Released 2015-12-25; 156 min; worldwide gross about US$533 million (TMDB); tagline: "(n. One who has returned, as if from the dead.)" | R29: Alejandro Gonz\u00e1lez I\u00f1\u00e1rritu | S29: Ryuichi Sakamoto & Carsten Nicolai | T29: Leonardo DiCaprio | U29: TMDB 5000 (vote count ≥300); cast from Wikipedia Movie Data | V29: Plot hint is source synopsis text – rewrite before launch; Hints rebuilt Oct 2026 for a 75–90% solve target | W29: 10 | X29: IMDb 965,251 votes · 8.0/10 · 73 Wikipedias · lead fame 149
A30: MOV-G-00318 | B30: Global | C30: Hollywood | D30: Easy | E30: The Silence of the Lambs | F30: Silence of the Lambs | G30: 1991 | H30: Genre: Crime, Drama · Hollywood · released 1991 | I30: Directed by: Jonathan Demme | J30: Moment: FBI trainee, ____ ventures into a maximum-security asylum to pick the diseased brain of ____, a psychiatrist turned homicidal cannibal. | K30: Co-stars: Jodie Foster, Scott Glenn | L30: Lead: Anthony Hopkins · music by Howard Shore | M30: Title initials: T. S. O. T. L. (5 words) | N30: Donnie Brasco | O30: Wild Things | P30: Sleepers | Q30: Released 1991-02-01; 119 min; worldwide gross about US$273 million (TMDB); tagline: "To enter the mind of a killer she must challenge the mind of a madman." | R30: Jonathan Demme | S30: Howard Shore | T30: Anthony Hopkins | U30: TMDB 5000 (vote count ≥300); cast from Wikipedia Movie Data | V30: Plot hint is source synopsis text – rewrite before launch; Hints rebuilt Oct 2026 for a 75–90% solve target | W30: 10 | X30: IMDb 1,758,444 votes · 8.6/10 · 102 Wikipedias · lead fame 120
A31: MOV-G-00319 | B31: Global | C31: Hollywood | D31: Easy | E31: The Sixth Sense | F31: Sixth Sense | G31: 1999 | H31: Genre: Drama, Mystery · Hollywood · released 1999 | I31: Directed by: M. Night Shyamalan | J31: Moment: A psychological thriller about an eight year old boy named ____ who believes he can see into the world of the dead. | K31: Co-stars: Haley Joel Osment, Toni Collette | L31: Lead: Bruce Willis · music by James Newton Howard | M31: Title initials: T. S. S. (3 words) | N31: The X Files | O31: Eyes Wide Shut | P31: Dark City | Q31: Released 1999-08-06; 107 min; worldwide gross about US$673 million (TMDB); tagline: "Not every gift is a blessing." | R31: M. Night Shyamalan | S31: James Newton Howard | T31: Bruce Willis | U31: TMDB 5000 (vote count ≥300); cast from Wikipedia Movie Data | V31: Plot hint is source synopsis text – rewrite before launch; Hints rebuilt Oct 2026 for a 75–90% solve target | W31: 10 | X31: IMDb 1,170,146 votes · 8.2/10 · 68 Wikipedias · lead fame 117
A32: MOV-G-00324 | B32: Global | C32: Hollywood | D32: Easy | E32: The Truman Show | F32: Truman Show | G32: 1998 | H32: Genre: Comedy, Drama · Hollywood · released 1998 | I32: Directed by: Peter Weir | J32: Moment: ____ is the star of "The ____", a 24-hour-a-day "reality" ____ that broadcasts every aspect of his life -- live and in color -- without his knowledge. | K32: Co-stars: Ed Harris, Laura Linney | L32: Lead: Jim Carrey · music by Burkhard von Dallwitz | M32: Title initials: T. T. S. (3 words) | N32: Mars Attacks! | O32: The Naked Gun 33⅓: The Final Insult | P32: Deuce Bigalow: Male Gigolo | Q32: Released 1998-06-04; 103 min; worldwide gross about US$264 million (TMDB); tagline: "On the air. Unaware." | R32: Peter Weir | S32: Burkhard von Dallwitz | T32: Jim Carrey | U32: TMDB 5000 (vote count ≥300); cast from Wikipedia Movie Data | V32: Plot hint is source synopsis text – rewrite before launch; Hints rebuilt Oct 2026 for a 75–90% solve target | W32: 10 | X32: IMDb 1,412,965 votes · 8.2/10 · 73 Wikipedias · lead fame 126
A33: MOV-G-00327 | B33: Global | C33: Hollywood | D33: Easy | E33: The Wolf of Wall Street | F33: Wolf of Wall Street | G33: 2013 | H33: Genre: Biography, Comedy · Hollywood · released 2013 | I33: Directed by: Martin Scorsese | J33: Moment: A ____ stockbroker refuses to cooperate in a large securities fraud case involving corruption on ____, corporate banking world and mob infiltration. | K33: Co-stars: Jonah Hill, Matthew McConaughey | L33: Lead: Leonardo DiCaprio · music by Bryan Carrigan & Meghan Currier | M33: Title initials: T. W. O. W. S. (5 words) | N33: Faster | O33: A Most Violent Year | P33: Edge of Darkness | Q33: Released 2013-12-25; 180 min; worldwide gross about US$392 million (TMDB); tagline: "EARN. SPEND. PARTY." | R33: Martin Scorsese | S33: Bryan Carrigan & Meghan Currier | T33: Leonardo DiCaprio | U33: TMDB 5000 (vote count ≥300); cast from Wikipedia Movie Data | V33: Plot hint is source synopsis text – rewrite before launch; Hints rebuilt Oct 2026 for a 75–90% solve target | W33: 10 | X33: IMDb 1,832,407 votes · 8.2/10 · 75 Wikipedias · lead fame 149
A34: MOV-G-00332 | B34: Global | C34: Hollywood | D34: Easy | E34: Titanic | G34: 1997 | H34: Genre: Drama, Romance · Hollywood · released 1997 | I34: Directed by: James Cameron | J34: Moment: 84 years later, a 101-year-old woman named ____ tells the story to her granddaughter ____ and ____ on the ____ about her life set in… | K34: Co-stars: Kate Winslet, Billy Zane | L34: Lead: Leonardo DiCaprio · music by James Horner | M34: Title: one word, 7 letters, starts with 'T' | N34: The Bone Collector | O34: Child's Play 2 | P34: Flatliners | Q34: Released 1997-11-18; 194 min; worldwide gross about US$1,845 million (TMDB); tagline: "Nothing on Earth could come between them." | R34: James Cameron | S34: James Horner | T34: Leonardo DiCaprio | U34: TMDB 5000 (vote count ≥300); cast from Wikipedia Movie Data | V34: Plot hint is source synopsis text – rewrite before launch; Hints rebuilt Oct 2026 for a 75–90% solve target | W34: 10 | X34: IMDb 1,416,970 votes · 8.0/10 · 137 Wikipedias · lead fame 149
A35: MOV-G-00337 | B35: Global | C35: Hollywood | D35: Easy | E35: Toy Story 3 | G35: 2010 | H35: Genre: Adventure, Animation · Hollywood · released 2010 | I35: Directed by: Lee Unkrich | J35: Moment: Woody, ____, and the rest of ____ haven't been played with in years. | K35: Co-stars: Tim Allen, Joan Cusack | L35: Lead: Tom Hanks · music by Randy Newman | M35: Title initials: T. S. 3. (3 words) | N35: The Smurfs | O35: Hop | P35: The Boxtrolls | Q35: Released 2010-06-16; 103 min; worldwide gross about US$1,067 million (TMDB); tagline: "No toy gets left behind." | R35: Lee Unkrich | S35: Randy Newman | T35: Tom Hanks | U35: TMDB 5000 (vote count ≥300); cast from Wikipedia Movie Data | V35: Plot hint is source synopsis text – rewrite before launch; Hints rebuilt Oct 2026 for a 75–90% solve target | W35: 10 | X35: IMDb 993,860 votes · 8.3/10 · 87 Wikipedias · lead fame 136
A36: MOV-G-00347 | B36: Global | C36: Hollywood | D36: Easy | E36: V for Vendetta | G36: 2006 | H36: Genre: Action, Drama · Hollywood · released 2006 | I36: Directed by: James McTeigue | J36: Moment: In a world in which ____ has become a fascist state, a masked vigilante known only as 'V' conducts guerrilla warfare against the oppressive ____ government. | K36: Co-stars: Hugo Weaving, Stephen Rea | L36: Lead: Natalie Portman · music by Dario Marianelli | M36: Title initials: V. F. V. (3 words) | N36: Around the World in 80 Days | O36: Righteous Kill | P36: Babylon A.D. | Q36: Released 2006-03-15; 132 min; worldwide gross about US$133 million (TMDB); tagline: "People should not be afraid of their governments. Governments should be afraid of their people." | R36: James McTeigue | S36: Dario Marianelli | T36: Natalie Portman | U36: TMDB 5000 (vote count ≥300); cast from Wikipedia Movie Data | V36: Plot hint is source synopsis text – rewrite before launch; Hints rebuilt Oct 2026 for a 75–90% solve target | W36: 10 | X36: IMDb 1,258,699 votes · 8.1/10 · 98 Wikipedias · lead fame 136
A37: MOV-G-00039 | B37: Global | C37: Hollywood | D37: Easy | E37: Black Swan | G37: 2010 | H37: Genre: Drama, Thriller · Hollywood · released 2010 | I37: Directed by: Darren Aronofsky | J37: Moment: A ballet dancer wins the lead in "____" and is perfect for the role of the delicate ____ - ____ - but slowly loses her mind as she becomes more and more like ____, the ____. | K37: Co-stars: Mila Kunis, Vincent Cassel | L37: Lead: Natalie Portman · music by Clint Mansell | M37: Title initials: B. S. (2 words) | N37: Arthur Christmas | O37: The Best Offer | P37: Monsters | Q37: Released 2010-12-02; 108 min; worldwide gross about US$328 million (TMDB); tagline: "In the era of personal branding, the scariest possibility is that someone might be better at being you than you are." | R37: Darren Aronofsky | S37: Clint Mansell | T37: Natalie Portman | U37: TMDB 5000 (vote count ≥300); cast from Wikipedia Movie Data | V37: Plot hint is source synopsis text – rewrite before launch; Hints rebuilt Oct 2026 for a 75–90% solve target | W37: 9.9 | X37: IMDb 899,757 votes · 8.0/10 · 74 Wikipedias · lead fame 136
A38: MOV-G-00151 | B38: Global | C38: Hollywood | D38: Easy | E38: Logan | G38: 2017 | H38: Genre: Action, Drama · Hollywood · released 2017 | I38: Directed by: James Mangold | J38: Moment: An ageing mutant protects a young girl who shares his claws | K38: Co-stars: Patrick Stewart, Boyd Holbrook | L38: Lead: Hugh Jackman · music by Marco Beltrami | M38: Title: one word, 5 letters, starts with 'L' | N38: The Grey | O38: The Interview | P38: Kick-Ass | Q38: Released 2017 | R38: James Mangold | S38: Marco Beltrami | T38: Hugh Jackman | U38: Curated by Claude; director and lead cross-checked against Wikipedia Movie Data where available | V38: Curated (2017–2025 gap in TMDB) – plot line written by Claude; Wikipedia cross-check: director OK, lead OK; Hints rebuilt Oct 2026 for a 75–90% solve target | W38: 9.9 | X38: IMDb 943,958 votes · 8.1/10 · 61 Wikipedias · lead fame 106
A39: MOV-G-00311 | B39: Global | C39: Hollywood | D39: Easy | E39: The Prestige | F39: Prestige | G39: 2006 | H39: Genre: Drama, Mystery · Hollywood · released 2006 | I39: Directed by: Christopher Nolan | J39: Moment: A mysterious story of two magicians whose intense rivalry leads them on a life-long battle for supremacy -- full of obsession, deceit and jealousy with dangerous and deadly consequences. | K39: Co-stars: Christian Bale, Michael Caine | L39: Lead: Hugh Jackman · music by David Julyan | M39: Title initials: T. P. (2 words) | N39: Lost in Translation | O39: Valkyrie | P39: Something's Gotta Give | Q39: Released 2006-10-19; 130 min; worldwide gross about US$110 million (TMDB); tagline: "Are You Watching Closely?" | R39: Christopher Nolan | S39: David Julyan | T39: Hugh Jackman | U39: TMDB 5000 (vote count ≥300); cast from Wikipedia Movie Data | V39: Plot hint is source synopsis text – rewrite before launch; Hints rebuilt Oct 2026 for a 75–90% solve target | W39: 9.9 | X39: IMDb 1,634,089 votes · 8.5/10 · 77 Wikipedias · lead fame 106
A40: MOV-G-00017 | B40: Global | C40: Hollywood | D40: Easy | E40: Alien | G40: 1979 | H40: Genre: Horror, Sci-Fi · Hollywood · released 1979 | I40: Directed by: Ridley Scott | J40: Moment: During its return to the earth, commercial spaceship ____ intercepts a distress signal from a distant planet. | K40: Co-stars: Tom Skerritt, Harry Dean Stanton | L40: Lead: Sigourney Weaver · music by Jerry Goldsmith | M40: Title: one word, 5 letters, starts with 'A' | N40: Jaws | O40: Halloween | P40: The Texas Chain Saw Massacre | Q40: Released 1979-05-25; 117 min; worldwide gross about US$105 million (TMDB); tagline: "In space no one can hear you scream." | R40: Ridley Scott | S40: Jerry Goldsmith | T40: Sigourney Weaver | U40: TMDB 5000 (vote count ≥300); cast from Wikipedia Movie Data | V40: Plot hint is source synopsis text – rewrite before launch; Hints rebuilt Oct 2026 for a 75–90% solve target | W40: 9.8 | X40: IMDb 1,080,095 votes · 8.4/10 · 83 Wikipedias · lead fame 122
...

Sheet Music
A1: ID | B1: Edition | C1: Answer type | D1: Difficulty | E1: Answer | F1: Accepted aliases | G1: Artist | H1: Year | I1: Hint 1 (shown at start) | J1: Hint 2 (after miss 1) | K1: Hint 3 (after miss 2) | L1: Hint 4 (after miss 3) | M1: Hint 5 (after miss 4) | N1: Hint 6 (after miss 5, with options) | O1: Wrong option A | P1: Wrong option B | Q1: Wrong option C | R1: Reveal-card fact | S1: Source | T1: Verify flag | U1: Fame score (0-10) | V1: Score signals
A2: MUS-G-00034 | B2: Global | C2: Song | D2: Easy | E2: All I Want For Christmas Is You | G2: Mariah Carey | H2: 2000 | I2: Vibe: Dance Pop · 2000 | J2: Chart: peaked at #1 on the Billboard Hot 100, 79 weeks on the chart | K2: Album: Merry ____ | L2: Same artist also charted with: 'We Belong Together' | M2: Artist: Mariah Carey | N2: Title initials: A. I. W. F. C. I. Y. (7 words) | O2: Baby Boy | P2: Sweet Dreams — Beyonce | Q2: Waking Up In Vegas | R2: All I Want For Christmas Is You by Mariah Carey; peak #1 on the Billboard Hot 100 (2000) | S2: Billboard Hot 100 weekly charts 1958–Oct 2026 (utdata/rwd-billboard-data); genre/album from Spotify via TidyTuesday 2021-09-14 | T2: Hints rebuilt Oct 2026 for a 75–90% solve target | U2: 10 | V2: peak #1 · 79 weeks · artist fame 126
A3: MUS-G-00054 | B3: Global | C3: Song | D3: Easy | E3: Anti-Hero | F3: AntiHero | G3: Taylor Swift | H3: 2022 | I3: Vibe: Chart hit · 2022 | J3: Chart: peaked at #1 on the Billboard Hot 100, 53 weeks on the chart | K3: Same artist also charted with: 'Cruel Summer' | L3: Chart year: entered the Hot 100 in 2022 | M3: Artist: Taylor Swift | N3: Title: one word, 9 letters, starts with 'A' | O3: Monster | P3: Something In The Orange | Q3: How It's Done | R3: Anti-Hero by Taylor Swift; peak #1 on the Billboard Hot 100 (2022) | S3: Billboard Hot 100 weekly charts 1958–Oct 2026 (utdata/rwd-billboard-data); genre/album from Spotify via TidyTuesday 2021-09-14 | T3: Hints rebuilt Oct 2026 for a 75–90% solve target | U3: 10 | V3: peak #1 · 53 weeks · artist fame 178
A4: MUS-G-00057 | B4: Global | C4: Artist/Band | D4: Easy | E4: Ariana Grande | G4: Ariana Grande | H4: 2014 | I4: Era: in the Hot 100 top 10 between 2015 and 2026 · Dance Pop | J4: Chart record: 14 top-10 hits, 6 #1 hit(s) on the Billboard Hot 100 | K4: First top-10 hit: 'Santa Tell Me' (2014) | L4: Number of words in name: 2 | M4: Biggest hit: 'Save Your Tears' | N4: Name: 2 words — 6 + 6 letters, initials A.G. | O4: Demi Lovato | P4: Harry Styles | Q4: Dua Lipa | R4: Ariana Grande: 14 Hot 100 top-10 hits (2014–2026) | S4: Billboard Hot 100 1958–Oct 2026; Rolling Stone 500 Albums via TidyTuesday 2024-05-07 | T4: Counts are solo-credited entries only (features excluded); Hints rebuilt Oct 2026 for a 75–90% solve target | U4: 10 | V4: fame 141 · 14 top-10s
A5: MUS-G-00070 | B5: Global | C5: Song | D5: Easy | E5: Bad Guy | G5: Billie Eilish | H5: 2019 | I5: Vibe: Electropop · 2019 | J5: Chart: peaked at #1 on the Billboard Hot 100, 49 weeks on the chart | K5: Album: WHEN WE ALL FALL ASLEE | L5: Same artist also charted with: 'Birds Of A Feather' | M5: Artist: Billie Eilish | N5: Title initials: B. G. (2 words) | O5: Roses — The Chainsmokers Featuring Rozes | P5: Don't Let Me Down | Q5: Paris | R5: Bad Guy by Billie Eilish; peak #1 on the Billboard Hot 100 (2019) | S5: Billboard Hot 100 weekly charts 1958–Oct 2026 (utdata/rwd-billboard-data); genre/album from Spotify via TidyTuesday 2021-09-14 | T5: Hints rebuilt Oct 2026 for a 75–90% solve target | U5: 10 | V5: peak #1 · 49 weeks · artist fame 125
A6: MUS-G-00097 | B6: Global | C6: Artist/Band | D6: Easy | E6: Beyonce | G6: Beyonce | H6: 2003 | I6: Era: in the Hot 100 top 10 between 2004 and 2024 · Dance Pop | J6: Chart record: 12 top-10 hits, 4 #1 hit(s) on the Billboard Hot 100 | K6: First top-10 hit: 'Me, Myself And I' (2003) | L6: Rolling Stone 500 (2020) album: 'Lemonade' (2016), ranked #32 | M6: Biggest hit: 'Irreplaceable' | N6: Name: one word, 7 letters, starts with 'B' | O6: Fergie | P6: Ne-Yo | Q6: Katy Perry | R6: Beyonce: 12 Hot 100 top-10 hits (2003–2024) | S6: Billboard Hot 100 1958–Oct 2026; Rolling Stone 500 Albums via TidyTuesday 2024-05-07 | T6: Counts are solo-credited entries only (features excluded); Hints rebuilt Oct 2026 for a 75–90% solve target | U6: 10 | V6: fame 175 · 12 top-10s
A7: MUS-G-00129 | B7: Global | C7: Artist/Band | D7: Easy | E7: Britney Spears | G7: Britney Spears | H7: 1998 | I7: Era: in the Hot 100 top 10 between 1998 and 2011 · Dance Pop | J7: Chart record: 10 top-10 hits, 4 #1 hit(s) on the Billboard Hot 100 | K7: First top-10 hit: '...Baby One More Time' (1998) | L7: Rolling Stone 500 (2020) album: 'Blackout' (2007), ranked #441 | M7: Biggest hit: '...Baby One More Time' | N7: Name: 2 words — 7 + 6 letters, initials B.S. | O7: Christina Aguilera | P7: En Vogue | Q7: Jennifer Lopez | R7: Britney Spears: 10 Hot 100 top-10 hits (1998–2011) | S7: Billboard Hot 100 1958–Oct 2026; Rolling Stone 500 Albums via TidyTuesday 2024-05-07 | T7: Counts are solo-credited entries only (features excluded); Hints rebuilt Oct 2026 for a 75–90% solve target | U7: 10 | V7: fame 146 · 10 top-10s
A8: MUS-G-00144 | B8: Global | C8: Song | D8: Easy | E8: Can't Stop The Feeling! | F8: Cant Stop The Feeling | G8: Justin Timberlake | H8: 2016 | I8: Vibe: Dance Pop · 2016 | J8: Chart: peaked at #1 on the Billboard Hot 100, 52 weeks on the chart | K8: Album: TROLLS (Original Motion Picture Soundtrack) | L8: Same artist also charted with: 'SexyBack' | M8: Artist: Justin Timberlake | N8: Title initials: C. S. T. F. (4 words) | O8: Mr. Know It All | P8: Firework | Q8: Habits (Stay High) | R8: Can't Stop The Feeling! by Justin Timberlake; peak #1 on the Billboard Hot 100 (2016) | S8: Billboard Hot 100 weekly charts 1958–Oct 2026 (utdata/rwd-billboard-data); genre/album from Spotify via TidyTuesday 2021-09-14 | T8: Hints rebuilt Oct 2026 for a 75–90% solve target | U8: 10 | V8: peak #1 · 52 weeks · artist fame 111
A9: MUS-G-00145 | B9: Global | C9: Song | D9: Easy | E9: Candle In The Wind 1997/Something About The Way You Look Tonight | F9: Candle In The Wind 1997Something About The Way You Look Tonight | G9: Elton John | H9: 1997 | I9: Vibe: Glam Rock · ____ | J9: Chart: peaked at #1 on the Billboard Hot 100, 42 weeks on the chart | K9: Same artist also charted with: 'Bennie And The Jets' | L9: Chart year: entered the Hot 100 in ____ | M9: Artist: Elton John | N9: Title initials: C. I. T. W. 1. S. A. T. W. Y. L. T. (12 words) | O9: The One | P9: Can You Feel The Love Tonight (From "The Lion King") | Q9: I Believe In You And Me (From "The Preacher's Wife") | R9: Candle In The Wind 1997/Something About The Way You Look Tonight by Elton John; peak #1 on the Billboard Hot 100 (1997) | S9: Billboard Hot 100 weekly charts 1958–Oct 2026 (utdata/rwd-billboard-data); genre/album from Spotify via TidyTuesday 2021-09-14 | T9: Hints rebuilt Oct 2026 for a 75–90% solve target | U9: 10 | V9: peak #1 · 42 weeks · artist fame 117
A10: MUS-G-00178 | B10: Global | C10: Song | D10: Easy | E10: Cruel Summer — Taylor Swift | F10: Cruel Summer Taylor Swift | G10: Taylor Swift | H10: 2019 | I10: Vibe: Dance Pop · 2019 | J10: Chart: peaked at #1 on the Billboard Hot 100, 54 weeks on the chart | K10: Album: Lover | L10: Same artist also charted with: 'Anti-Hero' | M10: Artist: ____ ____ | N10: Title initials: C. S. T. S. (4 words) | O10: Wild Thoughts | P10: Without Me — Halsey | Q10: Cooler Than Me | R10: Cruel Summer by Taylor Swift; peak #1 on the Billboard Hot 100 (2019) | S10: Billboard Hot 100 weekly charts 1958–Oct 2026 (utdata/rwd-billboard-data); genre/album from Spotify via TidyTuesday 2021-09-14 | T10: Hints rebuilt Oct 2026 for a 75–90% solve target | U10: 10 | V10: peak #1 · 54 weeks · artist fame 178
A11: MUS-G-00199 | B11: Global | C11: Song | D11: Easy | E11: Die For You — The Weeknd & Ariana Grande | F11: Die For You The Weeknd Ariana Grande | G11: The Weeknd & Ariana Grande | H11: 2023 | I11: Vibe: Chart hit · 2023 | J11: Chart: peaked at #1 on the Billboard Hot 100, 52 weeks on the chart | K11: Same artist also charted with: 'Save Your Tears' | L11: Chart year: entered the Hot 100 in 2023 | M11: Artist: The ____ & ____ ____ | N11: Title initials: D. F. Y. T. W. A. G. (7 words) | O11: II Most Wanted | P11: pride.is.the.devil | Q11: Hey Now | R11: Die For You by The Weeknd & Ariana Grande; peak #1 on the Billboard Hot 100 (2023) | S11: Billboard Hot 100 weekly charts 1958–Oct 2026 (utdata/rwd-billboard-data); genre/album from Spotify via TidyTuesday 2021-09-14 | T11: Hints rebuilt Oct 2026 for a 75–90% solve target | U11: 10 | V11: peak #1 · 52 weeks · artist fame 141
A12: MUS-G-00200 | B12: Global | C12: Song | D12: Easy | E12: Die With A Smile | G12: Lady Gaga & Bruno Mars | H12: 2024 | I12: Vibe: Chart hit · 2024 | J12: Chart: peaked at #1 on the Billboard Hot 100, 60 weeks on the chart | K12: Chart year: entered the Hot 100 in 2024 | L12: Artist initials: L.G.&.B.M. | M12: Artist: Lady Gaga & Bruno Mars | N12: Title initials: D. W. A. S. (4 words) | O12: Wants And Needs | P12: Super Freaky Girl | Q12: Stay — The Kid LAROI & Justin Bieber | R12: Die With A Smile by Lady Gaga & Bruno Mars; peak #1 on the Billboard Hot 100 (2024) | S12: Billboard Hot 100 weekly charts 1958–Oct 2026 (utdata/rwd-billboard-data); genre/album from Spotify via TidyTuesday 2021-09-14 | T12: Hints rebuilt Oct 2026 for a 75–90% solve target | U12: 10 | V12: peak #1 · 60 weeks · artist fame 197
A13: MUS-G-00244 | B13: Global | C13: Artist/Band | D13: Easy | E13: Eminem | G13: Eminem | H13: 2000 | I13: Era: in the Hot 100 top 10 between 2000 and 2024 · Detroit Hip Hop | J13: Chart record: 13 top-10 hits, 2 #1 hit(s) on the Billboard Hot 100 | K13: First top-10 hit: 'The Real Slim Shady' (2000) | L13: Rolling Stone 500 (2020) album: 'The Marshall Mathers LP' (2000), ranked #145 | M13: Biggest hit: 'Love The Way You Lie' | N13: Name: one word, 6 letters, starts with 'E' | O13: Fergie | P13: Miley Cyrus | Q13: Flo Rida | R13: Eminem: 13 Hot 100 top-10 hits (2000–2024) | S13: Billboard Hot 100 1958–Oct 2026; Rolling Stone 500 Albums via TidyTuesday 2024-05-07 | T13: Counts are solo-credited entries only (features excluded); Hints rebuilt Oct 2026 for a 75–90% solve target | U13: 10 | V13: fame 175 · 13 top-10s
A14: MUS-G-00273 | B14: Global | C14: Song | D14: Easy | E14: Flowers | G14: Miley Cyrus | H14: 2023 | I14: Vibe: Chart hit · 2023 | J14: Chart: peaked at #1 on the Billboard Hot 100, 55 weeks on the chart | K14: Same artist also charted with: 'Wrecking Ball' | L14: Chart year: entered the Hot 100 in 2023 | M14: Artist: Miley Cyrus | N14: Title: one word, 7 letters, starts with 'F' | O14: Save Your Tears — The Weeknd & Ariana Grande | P14: The Kind Of Love We Make | Q14: Super Gremlin | R14: Flowers by Miley Cyrus; peak #1 on the Billboard Hot 100 (2023) | S14: Billboard Hot 100 weekly charts 1958–Oct 2026 (utdata/rwd-billboard-data); genre/album from Spotify via TidyTuesday 2021-09-14 | T14: Hints rebuilt Oct 2026 for a 75–90% solve target | U14: 10 | V14: peak #1 · 55 weeks · artist fame 141
A15: MUS-G-00446 | B15: Global | C15: Artist/Band | D15: Easy | E15: Katy Perry | G15: Katy Perry | H15: 2008 | I15: Era: in the Hot 100 top 10 between 2008 and 2014 · Dance Pop | J15: Chart record: 10 top-10 hits, 6 #1 hit(s) on the Billboard Hot 100 | K15: First top-10 hit: 'I Kissed A Girl' (2008) | L15: Number of words in name: 2 | M15: Biggest hit: 'Dark Horse' | N15: Name: 2 words — 4 + 5 letters, initials K.P. | O15: OneRepublic | P15: Lady Gaga | Q15: Flo Rida | R15: Katy Perry: 10 Hot 100 top-10 hits (2008–2013) | S15: Billboard Hot 100 1958–Oct 2026; Rolling Stone 500 Albums via TidyTuesday 2024-05-07 | T15: Counts are solo-credited entries only (features excluded); Hints rebuilt Oct 2026 for a 75–90% solve target | U15: 10 | V15: fame 136 · 10 top-10s
A16: MUS-G-00460 | B16: Global | C16: Artist/Band | D16: Easy | E16: Lady Gaga | G16: Lady Gaga | H16: 2009 | I16: Era: in the Hot 100 top 10 between 2009 and 2020 · Dance Pop | J16: Chart record: 13 top-10 hits, 2 #1 hit(s) on the Billboard Hot 100 | K16: First top-10 hit: 'Poker Face' (2009) | L16: Rolling Stone 500 (2020) album: 'Born This Way' (2011), ranked #484 | M16: Biggest hit: 'Die With A Smile' | N16: Name: 2 words — 4 + 4 letters, initials L.G. | O16: Beyonce | P16: Akon | Q16: Fergie | R16: Lady Gaga: 13 Hot 100 top-10 hits (2009–2020) | S16: Billboard Hot 100 1958–Oct 2026; Rolling Stone 500 Albums via TidyTuesday 2024-05-07 | T16: Counts are solo-credited entries only (features excluded); Hints rebuilt Oct 2026 for a 75–90% solve target | U16: 10 | V16: fame 197 · 13 top-10s
A17: MUS-G-00507 | B17: Global | C17: Song | D17: Easy | E17: Love Yourself | G17: Justin Bieber | H17: 2015 | I17: Vibe: Canadian Pop · 2015 | J17: Chart: peaked at #1 on the Billboard Hot 100, 41 weeks on the chart | K17: Album: Purpose (Deluxe) | L17: Same artist also charted with: 'Sorry' | M17: Artist: Justin Bieber | N17: Title initials: L. Y. (2 words) | O17: Call Me Maybe | P17: Senorita | Q17: If I Can't Have You — Shawn Mendes | R17: Love Yourself by Justin Bieber; peak #1 on the Billboard Hot 100 (2015) | S17: Billboard Hot 100 weekly charts 1958–Oct 2026 (utdata/rwd-billboard-data); genre/album from Spotify via TidyTuesday 2021-09-14 | T17: Hints rebuilt Oct 2026 for a 75–90% solve target | U17: 10 | V17: peak #1 · 41 weeks · artist fame 180
